* Serving Flask app 'app'
 * Debug mode: off
WARNING: This is a development server. Do not use it in a production deployment. Use a production WSGI server instead.
 * Running on all addresses (0.0.0.0)
 * Running on http://127.0.0.1:5000
 * Running on http://172.31.196.115:5000
Press CTRL+C to quit
172.31.196.115 - - [19/Sep/2024 14:25:55] "GET / HTTP/1.1" 200 -
172.31.196.115 - - [19/Sep/2024 14:25:55] "GET /static/css/tailwind.css HTTP/1.1" 304 -
172.31.196.115 - - [19/Sep/2024 14:25:55] "GET /static/js/main.js HTTP/1.1" 304 -
172.31.196.115 - - [19/Sep/2024 14:25:57] "GET / HTTP/1.1" 200 -
172.31.196.115 - - [19/Sep/2024 14:25:57] "GET /static/css/tailwind.css HTTP/1.1" 200 -
172.31.196.115 - - [19/Sep/2024 14:25:57] "GET /static/js/main.js HTTP/1.1" 200 -
172.31.196.115 - - [19/Sep/2024 14:26:12] "GET / HTTP/1.1" 200 -
172.31.196.115 - - [19/Sep/2024 14:26:12] "GET /static/css/tailwind.css HTTP/1.1" 304 -
172.31.196.115 - - [19/Sep/2024 14:26:12] "GET /static/js/main.js HTTP/1.1" 304 -
[2024-09-19 14:28:44,278] ERROR in app: Exception on /chat [POST]
Traceback (most recent call last):
  File "/home/runner/ProjectExplorer/.pythonlibs/lib/python3.11/site-packages/flask/app.py", line 1473, in wsgi_app
    response = self.full_dispatch_request()
               ^^^^^^^^^^^^^^^^^^^^^^^^^^^^
  File "/home/runner/ProjectExplorer/.pythonlibs/lib/python3.11/site-packages/flask/app.py", line 882, in full_dispatch_request
    rv = self.handle_user_exception(e)
         ^^^^^^^^^^^^^^^^^^^^^^^^^^^^^
  File "/home/runner/ProjectExplorer/.pythonlibs/lib/python3.11/site-packages/flask/app.py", line 880, in full_dispatch_request
    rv = self.dispatch_request()
         ^^^^^^^^^^^^^^^^^^^^^^^
  File "/home/runner/ProjectExplorer/.pythonlibs/lib/python3.11/site-packages/flask/app.py", line 865, in dispatch_request
    return self.ensure_sync(self.view_functions[rule.endpoint])(**view_args)  # type: ignore[no-any-return]
           ^^^^^^^^^^^^^^^^^^^^^^^^^^^^^^^^^^^^^^^^^^^^^^^^^^^^^^^^^^^^^^^^^
  File "/home/runner/ProjectExplorer/app/routes.py", line 43, in chat
    responses[provider] = llm.generate_response(message)
                          ^^^^^^^^^^^^^^^^^^^^^^^^^^^^^^
  File "/home/runner/ProjectExplorer/app/llm_providers.py", line 64, in generate_response
    gemini_history.append(content_types.Content(role='user', parts=[content_types.Part(text=entry['content'])]))
                          ^^^^^^^^^^^^^^^^^^^^^
AttributeError: module 'google.generativeai.types.content_types' has no attribute 'Content'
172.31.196.115 - - [19/Sep/2024 14:28:44] "POST /chat HTTP/1.1" 500 -
172.31.196.115 - - [19/Sep/2024 14:30:46] "POST /clear_history HTTP/1.1" 200 -
172.31.196.115 - - [19/Sep/2024 14:30:46] "POST /clear_history HTTP/1.1" 200 -
[2024-09-19 14:30:49,375] ERROR in app: Exception on /chat [POST]
Traceback (most recent call last):
  File "/home/runner/ProjectExplorer/.pythonlibs/lib/python3.11/site-packages/flask/app.py", line 1473, in wsgi_app
    response = self.full_dispatch_request()
               ^^^^^^^^^^^^^^^^^^^^^^^^^^^^
  File "/home/runner/ProjectExplorer/.pythonlibs/lib/python3.11/site-packages/flask/app.py", line 882, in full_dispatch_request
    rv = self.handle_user_exception(e)
         ^^^^^^^^^^^^^^^^^^^^^^^^^^^^^
  File "/home/runner/ProjectExplorer/.pythonlibs/lib/python3.11/site-packages/flask/app.py", line 880, in full_dispatch_request
    rv = self.dispatch_request()
         ^^^^^^^^^^^^^^^^^^^^^^^
  File "/home/runner/ProjectExplorer/.pythonlibs/lib/python3.11/site-packages/flask/app.py", line 865, in dispatch_request
    return self.ensure_sync(self.view_functions[rule.endpoint])(**view_args)  # type: ignore[no-any-return]
           ^^^^^^^^^^^^^^^^^^^^^^^^^^^^^^^^^^^^^^^^^^^^^^^^^^^^^^^^^^^^^^^^^
  File "/home/runner/ProjectExplorer/app/routes.py", line 43, in chat
    responses[provider] = llm.generate_response(message)
                          ^^^^^^^^^^^^^^^^^^^^^^^^^^^^^^
  File "/home/runner/ProjectExplorer/app/llm_providers.py", line 64, in generate_response
    gemini_history.append(content_types.Content(role='user', parts=[content_types.Part(text=entry['content'])]))
                          ^^^^^^^^^^^^^^^^^^^^^
AttributeError: module 'google.generativeai.types.content_types' has no attribute 'Content'
172.31.196.115 - - [19/Sep/2024 14:30:49] "POST /chat HTTP/1.1" 500 -
